Workbook

Sheet Transactions_View
A1: transaction_id | B1: user_id | C1: merchant_id | D1: transaction_time | E1: amount_inr | F1: payment_method | G1: status | H1: risk_score | I1: merchant_name | J1: category | K1: region | L1: MDR Fee % | M1: Daily Merchant Total | N1: Merchant Day Classification | O1: transaction_date
A2: TXN100000 | B2: 350 | C2: 16 | D2: 46051.467 | E2: 2999 | F2: Wallet | G2: captured | H2: 85 | I2: =IFERROR(VLOOKUP(C2,Merchants!$A$2:$D$41,2,FALSE),"Merchant not found") -> Merchant_016 | J2: =IFERROR(VLOOKUP(C2,Merchants!$A$2:$D$41,3,FALSE),"Merchant not found") -> bill_payment | K2: =IFERROR(VLOOKUP(C2,Merchants!$A$2:$D$41,4,FALSE), "Merchant Not Fount") -> West | L2: =HLOOKUP(F2,HLOOKUP_Reference!$A$1:$E$2,2,FALSE) -> 0.0065 | M2: =SUMIFS(Daily_Merchant_Pivot!$E:$E,Daily_Merchant_Pivot!$A:$A,C2,Daily_Merchant_Pivot!$D:$D,INT(D2)) -> 2999 | N2: =IF(AND(M2>5000,K2<>"East"),"High-Value Merchant Day","Normal Merchant Day") -> Normal Merchant Day | O2: =INT(D2) -> 46051
A3: TXN100001 | B3: 287 | C3: 27 | D3: 46026.492 | E3: 49 | F3: UPI | G3: captured | H3: 79 | I3: =IFERROR(VLOOKUP(C3,Merchants!$A$2:$D$41,2,FALSE),"Merchant not found") -> Merchant_027 | J3: =IFERROR(VLOOKUP(C3,Merchants!$A$2:$D$41,3,FALSE),"Merchant not found") -> ecommerce | K3: =IFERROR(VLOOKUP(C3,Merchants!$A$2:$D$41,4,FALSE), "Merchant Not Fount") -> North | L3: =HLOOKUP(F3,HLOOKUP_Reference!$A$1:$E$2,2,FALSE) -> 0.002 | M3: =SUMIFS(Daily_Merchant_Pivot!$E:$E,Daily_Merchant_Pivot!$A:$A,C3,Daily_Merchant_Pivot!$D:$D,INT(D3)) -> 49 | N3: =IF(AND(M3>5000,K3<>"East"),"High-Value Merchant Day","Normal Merchant Day") -> Normal Merchant Day | O3: =INT(D3) -> 46026
A4: TXN100002 | B4: 122 | C4: 11 | D4: 46046.208 | E4: 1499 | F4: Wallet | G4: captured | H4: 22 | I4: =IFERROR(VLOOKUP(C4,Merchants!$A$2:$D$41,2,FALSE),"Merchant not found") -> Merchant_011 | J4: =IFERROR(VLOOKUP(C4,Merchants!$A$2:$D$41,3,FALSE),"Merchant not found") -> ecommerce | K4: =IFERROR(VLOOKUP(C4,Merchants!$A$2:$D$41,4,FALSE), "Merchant Not Fount") -> North | L4: =HLOOKUP(F4,HLOOKUP_Reference!$A$1:$E$2,2,FALSE) -> 0.0065 | M4: =SUMIFS(Daily_Merchant_Pivot!$E:$E,Daily_Merchant_Pivot!$A:$A,C4,Daily_Merchant_Pivot!$D:$D,INT(D4)) -> 1798 | N4: =IF(AND(M4>5000,K4<>"East"),"High-Value Merchant Day","Normal Merchant Day") -> Normal Merchant Day | O4: =INT(D4) -> 46046
A5: TXN100003 | B5: 92 | C5: 22 | D5: 46051.542 | E5: 49 | F5: Netbanking | G5: captured | H5: 100 | I5: =IFERROR(VLOOKUP(C5,Merchants!$A$2:$D$41,2,FALSE),"Merchant not found") -> Merchant_022 | J5: =IFERROR(VLOOKUP(C5,Merchants!$A$2:$D$41,3,FALSE),"Merchant not found") -> travel | K5: =IFERROR(VLOOKUP(C5,Merchants!$A$2:$D$41,4,FALSE), "Merchant Not Fount") -> South | L5: =HLOOKUP(F5,HLOOKUP_Reference!$A$1:$E$2,2,FALSE) -> 0.01 | M5: =SUMIFS(Daily_Merchant_Pivot!$E:$E,Daily_Merchant_Pivot!$A:$A,C5,Daily_Merchant_Pivot!$D:$D,INT(D5)) -> 49 | N5: =IF(AND(M5>5000,K5<>"East"),"High-Value Merchant Day","Normal Merchant Day") -> Normal Merchant Day | O5: =INT(D5) -> 46051
A6: TXN100004 | B6: 343 | C6: 16 | D6: 46052.577 | E6: 99 | F6: UPI | G6: captured | H6: 34 | I6: =IFERROR(VLOOKUP(C6,Merchants!$A$2:$D$41,2,FALSE),"Merchant not found") -> Merchant_016 | J6: =IFERROR(VLOOKUP(C6,Merchants!$A$2:$D$41,3,FALSE),"Merchant not found") -> bill_payment | K6: =IFERROR(VLOOKUP(C6,Merchants!$A$2:$D$41,4,FALSE), "Merchant Not Fount") -> West | L6: =HLOOKUP(F6,HLOOKUP_Reference!$A$1:$E$2,2,FALSE) -> 0.002 | M6: =SUMIFS(Daily_Merchant_Pivot!$E:$E,Daily_Merchant_Pivot!$A:$A,C6,Daily_Merchant_Pivot!$D:$D,INT(D6)) -> 898 | N6: =IF(AND(M6>5000,K6<>"East"),"High-Value Merchant Day","Normal Merchant Day") -> Normal Merchant Day | O6: =INT(D6) -> 46052
A7: TXN100005 | B7: 196 | C7: 3 | D7: 46028.921 | E7: 99 | F7: UPI | G7: captured | H7: 60 | I7: =IFERROR(VLOOKUP(C7,Merchants!$A$2:$D$41,2,FALSE),"Merchant not found") -> Merchant_003 | J7: =IFERROR(VLOOKUP(C7,Merchants!$A$2:$D$41,3,FALSE),"Merchant not found") -> grocery | K7: =IFERROR(VLOOKUP(C7,Merchants!$A$2:$D$41,4,FALSE), "Merchant Not Fount") -> East | L7: =HLOOKUP(F7,HLOOKUP_Reference!$A$1:$E$2,2,FALSE) -> 0.002 | M7: =SUMIFS(Daily_Merchant_Pivot!$E:$E,Daily_Merchant_Pivot!$A:$A,C7,Daily_Merchant_Pivot!$D:$D,INT(D7)) -> 898 | N7: =IF(AND(M7>5000,K7<>"East"),"High-Value Merchant Day","Normal Merchant Day") -> Normal Merchant Day | O7: =INT(D7) -> 46028
A8: TXN100006 | B8: 236 | C8: 23 | D8: 46030.286 | E8: 99 | F8: Wallet | G8: captured | H8: 39 | I8: =IFERROR(VLOOKUP(C8,Merchants!$A$2:$D$41,2,FALSE),"Merchant not found") -> Merchant_023 | J8: =IFERROR(VLOOKUP(C8,Merchants!$A$2:$D$41,3,FALSE),"Merchant not found") -> travel | K8: =IFERROR(VLOOKUP(C8,Merchants!$A$2:$D$41,4,FALSE), "Merchant Not Fount") -> North | L8: =HLOOKUP(F8,HLOOKUP_Reference!$A$1:$E$2,2,FALSE) -> 0.0065 | M8: =SUMIFS(Daily_Merchant_Pivot!$E:$E,Daily_Merchant_Pivot!$A:$A,C8,Daily_Merchant_Pivot!$D:$D,INT(D8)) -> 99 | N8: =IF(AND(M8>5000,K8<>"East"),"High-Value Merchant Day","Normal Merchant Day") -> Normal Merchant Day | O8: =INT(D8) -> 46030
A9: TXN100007 | B9: 13 | C9: 13 | D9: 46049.301 | E9: 99 | F9: UPI | G9: captured | H9: 51 | I9: =IFERROR(VLOOKUP(C9,Merchants!$A$2:$D$41,2,FALSE),"Merchant not found") -> Merchant_013 | J9: =IFERROR(VLOOKUP(C9,Merchants!$A$2:$D$41,3,FALSE),"Merchant not found") -> travel | K9: =IFERROR(VLOOKUP(C9,Merchants!$A$2:$D$41,4,FALSE), "Merchant Not Fount") -> East | L9: =HLOOKUP(F9,HLOOKUP_Reference!$A$1:$E$2,2,FALSE) -> 0.002 | M9: =SUMIFS(Daily_Merchant_Pivot!$E:$E,Daily_Merchant_Pivot!$A:$A,C9,Daily_Merchant_Pivot!$D:$D,INT(D9)) -> 99 | N9: =IF(AND(M9>5000,K9<>"East"),"High-Value Merchant Day","Normal Merchant Day") -> Normal Merchant Day | O9: =INT(D9) -> 46049
A10: TXN100008 | B10: 36 | C10: 18 | D10: 46033.372 | E10: 799 | F10: UPI | G10: captured | H10: 44 | I10: =IFERROR(VLOOKUP(C10,Merchants!$A$2:$D$41,2,FALSE),"Merchant not found") -> Merchant_018 | J10: =IFERROR(VLOOKUP(C10,Merchants!$A$2:$D$41,3,FALSE),"Merchant not found") -> grocery | K10: =IFERROR(VLOOKUP(C10,Merchants!$A$2:$D$41,4,FALSE), "Merchant Not Fount") -> West | L10: =HLOOKUP(F10,HLOOKUP_Reference!$A$1:$E$2,2,FALSE) -> 0.002 | M10: =SUMIFS(Daily_Merchant_Pivot!$E:$E,Daily_Merchant_Pivot!$A:$A,C10,Daily_Merchant_Pivot!$D:$D,INT(D10)) -> 799 | N10: =IF(AND(M10>5000,K10<>"East"),"High-Value Merchant Day","Normal Merchant Day") -> Normal Merchant Day | O10: =INT(D10) -> 46033
A11: TXN100009 | B11: 348 | C11: 35 | D11: 46043.684 | E11: 299 | F11: UPI | G11: captured | H11: 42 | I11: =IFERROR(VLOOKUP(C11,Merchants!$A$2:$D$41,2,FALSE),"Merchant not found") -> Merchant_035 | J11: =IFERROR(VLOOKUP(C11,Merchants!$A$2:$D$41,3,FALSE),"Merchant not found") -> recharge | K11: =IFERROR(VLOOKUP(C11,Merchants!$A$2:$D$41,4,FALSE), "Merchant Not Fount") -> East | L11: =HLOOKUP(F11,HLOOKUP_Reference!$A$1:$E$2,2,FALSE) -> 0.002 | M11: =SUMIFS(Daily_Merchant_Pivot!$E:$E,Daily_Merchant_Pivot!$A:$A,C11,Daily_Merchant_Pivot!$D:$D,INT(D11)) -> 299 | N11: =IF(AND(M11>5000,K11<>"East"),"High-Value Merchant Day","Normal Merchant Day") -> Normal Merchant Day | O11: =INT(D11) -> 46043
A12: TXN100010 | B12: 134 | C12: 12 | D12: 46023.164 | E12: 49 | F12: UPI | G12: captured | H12: 74 | I12: =IFERROR(VLOOKUP(C12,Merchants!$A$2:$D$41,2,FALSE),"Merchant not found") -> Merchant_012 | J12: =IFERROR(VLOOKUP(C12,Merchants!$A$2:$D$41,3,FALSE),"Merchant not found") -> ecommerce | K12: =IFERROR(VLOOKUP(C12,Merchants!$A$2:$D$41,4,FALSE), "Merchant Not Fount") -> East | L12: =HLOOKUP(F12,HLOOKUP_Reference!$A$1:$E$2,2,FALSE) -> 0.002 | M12: =SUMIFS(Daily_Merchant_Pivot!$E:$E,Daily_Merchant_Pivot!$A:$A,C12,Daily_Merchant_Pivot!$D:$D,INT(D12)) -> 548 | N12: =IF(AND(M12>5000,K12<>"East"),"High-Value Merchant Day","Normal Merchant Day") -> Normal Merchant Day | O12: =INT(D12) -> 46023
A13: TXN100011 | B13: 306 | C13: 28 | D13: 46031.046 | E13: 2999 | F13: Card | G13: failed | H13: 44 | I13: =IFERROR(VLOOKUP(C13,Merchants!$A$2:$D$41,2,FALSE),"Merchant not found") -> Merchant_028 | J13: =IFERROR(VLOOKUP(C13,Merchants!$A$2:$D$41,3,FALSE),"Merchant not found") -> ecommerce | K13: =IFERROR(VLOOKUP(C13,Merchants!$A$2:$D$41,4,FALSE), "Merchant Not Fount") -> South | L13: =HLOOKUP(F13,HLOOKUP_Reference!$A$1:$E$2,2,FALSE) -> 0.015 | M13: =SUMIFS(Daily_Merchant_Pivot!$E:$E,Daily_Merchant_Pivot!$A:$A,C13,Daily_Merchant_Pivot!$D:$D,INT(D13)) -> 2999 | N13: =IF(AND(M13>5000,K13<>"East"),"High-Value Merchant Day","Normal Merchant Day") -> Normal Merchant Day | O13: =INT(D13) -> 46031
... A548: TXN300031 | B548: 345 | C548: 12 | D548: 46045.377 | E548: 399 | F548: Card | G548: captured | H548: 69 | I548: =IFERROR(VLOOKUP(C548,Merchants!$A$2:$D$41,2,FALSE),"Merchant not found") -> Merchant_012 | J548: =IFERROR(VLOOKUP(C548,Merchants!$A$2:$D$41,3,FALSE),"Merchant not found") -> ecommerce | K548: =IFERROR(VLOOKUP(C548,Merchants!$A$2:$D$41,4,FALSE), "Merchant Not Fount") -> East | L548: =HLOOKUP(F548,HLOOKUP_Reference!$A$1:$E$2,2,FALSE) -> 0.015 | M548: =SUMIFS(Daily_Merchant_Pivot!$E:$E,Daily_Merchant_Pivot!$A:$A,C548,Daily_Merchant_Pivot!$D:$D,INT(D548)) -> 448 | N548: =IF(AND(M548>5000,K548<>"East"),"High-Value Merchant Day","Normal Merchant Day") -> Normal Merchant Day | O548: =INT(D548) -> 46045

Sheet Merchants
A1: merchant_id | B1: merchant_name | C1: category | D1: region
A2: 1 | B2: Merchant_001 | C2: ecommerce | D2: South
A3: 2 | B3: Merchant_002 | C3: grocery | D3: West
A4: 3 | B4: Merchant_003 | C4: grocery | D4: East
A5: 4 | B5: Merchant_004 | C5: ecommerce | D5: East
A6: 5 | B6: Merchant_005 | C6: recharge | D6: South
A7: 6 | B7: Merchant_006 | C7: food_delivery | D7: South
A8: 7 | B8: Merchant_007 | C8: food_delivery | D8: East
A9: 8 | B9: Merchant_008 | C9: food_delivery | D9: North
A10: 9 | B10: Merchant_009 | C10: ecommerce | D10: North
A11: 10 | B11: Merchant_010 | C11: grocery | D11: West
A12: 11 | B12: Merchant_011 | C12: ecommerce | D12: North
A13: 12 | B13: Merchant_012 | C13: ecommerce | D13: East
... A41: 40 | B41: Merchant_040 | C41: entertainment | D41: South

Sheet HLOOKUP_Reference
A1: Payment Method | B1: UPI | C1: Wallet | D1: Card | E1: Netbanking
A2: MDR Fee % | B2: 0.002 | C2: 0.0065 | D2: 0.015 | E2: 0.01
A5: Assumption: MDR-style fee percentages are illustrative for HLOOKUP demonstration

Sheet Daily_Merchant_Pivot
A3: merchant_id | B3: Years (transaction_time) | C3: Months (transaction_time) | D3: Days (transaction_time) | E3: Sum of amount_inr
A4: 1 | B4: 2026 | C4: Jan | D4: 05-Jan | E4: 1499
A5: 1 | B5: 2026 | C5: Jan | D5: 06-Jan | E5: 149
A6: 1 | B6: 2026 | C6: Jan | D6: 09-Jan | E6: 5048
A7: 1 | B7: 2026 | C7: Jan | D7: 11-Jan | E7: 299
A8: 1 | B8: 2026 | C8: Jan | D8: 12-Jan | E8: 149
A9: 1 | B9: 2026 | C9: Jan | D9: 17-Jan | E9: 149
A10: 1 | B10: 2026 | C10: Jan | D10: 23-Jan | E10: 3148
A11: 2 | B11: 2026 | C11: Jan | D11: 07-Jan | E11: 499
A12: 2 | B12: 2026 | C12: Jan | D12: 08-Jan | E12: 299
A13: 2 | B13: 2026 | C13: Jan | D13: 12-Jan | E13: 348
A14: 2 | B14: 2026 | C14: Jan | D14: 13-Jan | E14: 49
A15: 2 | B15: 2026 | C15: Jan | D15: 15-Jan | E15: 1499
... A446: 40 | B446: 2026 | C446: Jan | D446: 30-Jan | E446: 499

Sheet Merchant_Status_Pivot
B3: status | C3: Values
B4: captured | D4: chargeback | F4: failed | H4: Total Count of transaction_id | I4: Total Sum of amount_inr
A5: merchant_id | B5: Count of transaction_id | C5: Sum of amount_inr | D5: Count of transaction_id | E5: Sum of amount_inr | F5: Count of transaction_id | G5: Sum of amount_inr
A6: 1 | B6: 8 | C6: 10142 | F6: 1 | G6: 299 | H6: 9 | I6: 10441
A7: 2 | B7: 10 | C7: 3640 | H7: 10 | I7: 3640
A8: 3 | B8: 16 | C8: 8084 | D8: 1 | E8: 149 | H8: 17 | I8: 8233
A9: 4 | B9: 9 | C9: 6941 | H9: 9 | I9: 6941
A10: 5 | B10: 10 | C10: 5340 | F10: 1 | G10: 499 | H10: 11 | I10: 5839
A11: 6 | B11: 13 | C11: 6637 | D11: 1 | E11: 799 | H11: 14 | I11: 7436
A12: 7 | B12: 12 | C12: 11638 | D12: 1 | E12: 1999 | F12: 3 | G12: 2297 | H12: 16 | I12: 15934
A13: 8 | B13: 14 | C13: 7086 | D13: 1 | E13: 49 | F13: 1 | G13: 299 | H13: 16 | I13: 7434
A14: 9 | B14: 15 | C14: 4485 | F14: 3 | G14: 497 | H14: 18 | I14: 4982
A15: 10 | B15: 11 | C15: 7639 | D15: 2 | E15: 5048 | F15: 1 | G15: 399 | H15: 14 | I15: 13086
A16: 11 | B16: 8 | C16: 9292 | D16: 1 | E16: 149 | F16: 1 | G16: 1499 | H16: 10 | I16: 10940
A17: 12 | B17: 11 | C17: 9389 | F17: 2 | G17: 998 | H17: 13 | I17: 10387
A18: 13 | B18: 10 | C18: 10390 | D18: 1 | E18: 4999 | F18: 1 | G18: 2999 | H18: 12 | I18: 18388
A19: 14 | B19: 11 | C19: 6189 | F19: 1 | G19: 299 | H19: 12 | I19: 6488
A20: 15 | B20: 11 | C20: 7439 | F20: 1 | G20: 399 | H20: 12 | I20: 7838
A21: 16 | B21: 17 | C21: 10183 | F21: 3 | G21: 947 | H21: 20 | I21: 11130
A22: 17 | B22: 12 | C22: 12738 | F22: 1 | G22: 299 | H22: 13 | I22: 13037
A23: 18 | B23: 11 | C23: 7089 | H23: 11 | I23: 7089
A24: 19 | B24: 11 | C24: 7239 | D24: 1 | E24: 4999 | F24: 2 | G24: 598 | H24: 14 | I24: 12836
A25: 20 | B25: 8 | C25: 4192 | F25: 1 | G25: 49 | H25: 9 | I25: 4241
A26: 21 | B26: 13 | C26: 3887 | F26: 1 | G26: 4999 | H26: 14 | I26: 8886
A27: 22 | B27: 14 | C27: 11336 | F27: 2 | G27: 1198 | H27: 16 | I27: 12534
A28: 23 | B28: 9 | C28: 1041 | D28: 1 | E28: 1999 | H28: 10 | I28: 3040
A29: 24 | B29: 12 | C29: 3438 | D29: 1 | E29: 149 | H29: 13 | I29: 3587
A30: 25 | B30: 16 | C30: 12534 | D30: 1 | E30: 2999 | H30: 17 | I30: 15533
A31: 26 | B31: 9 | C31: 2991 | F31: 3 | G31: 2197 | H31: 12 | I31: 5188
A32: 27 | B32: 12 | C32: 8038 | D32: 3 | E32: 4047 | F32: 1 | G32: 1499 | H32: 16 | I32: 13584
A33: 28 | B33: 7 | C33: 4493 | D33: 1 | E33: 1999 | F33: 2 | G33: 3048 | H33: 10 | I33: 9540
A34: 29 | B34: 14 | C34: 5686 | D34: 3 | E34: 3897 | F34: 2 | G34: 3498 | H34: 19 | I34: 13081
A35: 30 | B35: 16 | C35: 7384 | F35: 1 | G35: 499 | H35: 17 | I35: 7883
A36: 31 | B36: 10 | C36: 2640 | D36: 1 | E36: 49 | F36: 4 | G36: 2146 | H36: 15 | I36: 4835
A37: 32 | B37: 11 | C37: 2589 | D37: 1 | E37: 1999 | F37: 2 | G37: 3498 | H37: 14 | I37: 8086
A38: 33 | B38: 10 | C38: 10190 | F38: 1 | G38: 149 | H38: 11 | I38: 10339
A39: 34 | B39: 15 | C39: 9635 | F39: 1 | G39: 399 | H39: 16 | I39: 10034
A40: 35 | B40: 12 | C40: 8688 | F40: 2 | G40: 598 | H40: 14 | I40: 9286
A41: 36 | B41: 15 | C41: 11535 | D41: 1 | E41: 999 | H41: 16 | I41: 12534
A42: 37 | B42: 17 | C42: 10833 | D42: 1 | E42: 1999 | F42: 1 | G42: 99 | H42: 19 | I42: 12931
...

Sheet Merchant_Day_Comparison
A3: Row Labels | B3: Count of transaction_id | C3: Distinct Count of transaction_date
A4: 1 | B4: 9 | C4: 7
A5: 2 | B5: 10 | C5: 9
A6: 3 | B6: 17 | C6: 13
A7: 4 | B7: 9 | C7: 7
A8: 5 | B8: 11 | C8: 9
A9: 6 | B9: 14 | C9: 12
A10: 7 | B10: 16 | C10: 11
A11: 8 | B11: 16 | C11: 13
A12: 9 | B12: 18 | C12: 14
A13: 10 | B13: 14 | C13: 12
A14: 11 | B14: 10 | C14: 9
A15: 12 | B15: 13 | C15: 9
... A43: 40 | B43: 15 | C43: 13
A44: Grand Total | B44: 547 | C44: 30
